Workbook

Sheet Sheet1
T1: Confirmado por bodega
A2: name | B2: referencia interna | C2: image_1920 | D2: Largo | E2: Ancho | F2: Altura | G2: cbm | H2: costo dlls | I2: Unidades | J2: unidades por caja | K2: CBM por caja | L2: Tipo de producto | M2: Empresa | N2: Código de Barras | O2: contenedor | P2: COSTO LANDED MXN | Q2: DESCRIPCION | R2: CATEGORIA | S2: atributo | T2: CANTIDAD DE CAJAS | U2: PIEZAS POR CAJA | V2: PIEZAS X PACK | W2: PIEZAS TOTALES
A3: PLUMONES 48 COLORES | B3: EST-0060-48PZ | C3: =VLOOKUP(B3,Sheet2!$1:$1048576,2,FALSE) -> https://drive.google.com/uc?export=download&id=1h3fHGKZdZkuAsrYO7-GyEu7TL3W5BEKv | D3: 63 | E3: 44 | F3: 32 | G3: =D3*E3*F3/1000000 -> 0.088704 | H3: 8 | J3: 34 | K3: =J3*G3 -> 3.015936 | L3: Producto almacenable | M3: FERRAFORME MS | N3: EST-0060-48PZ | O3: EMCU8340494=CI&PL contenedor 36
A4: BOLSA TRANSPARENTE | B4: ORG-0288-PLA | C4: =VLOOKUP(B4,Sheet2!$1:$1048576,2,FALSE) -> https://drive.google.com/uc?export=download&id=1mVJp7sjujT7Q38wAJbx0teRSVjlrYJ48 | D4: 1 | E4: 1 | F4: 1 | H4: 4 | J4: 2 | K4: =J4*G4 -> 0 | L4: Producto almacenable | M4: FERRAFORME MS | N4: ORG-0288-PLA | O4: EMCU8340494=CI&PL contenedor 36
A5: AUDIFONOS INALAMBRICOS BLANCOS | B5: TEC-0455-PLA | C5: =VLOOKUP(B5,Sheet2!$1:$1048576,2,FALSE) -> https://drive.google.com/uc?export=download&id=1_mMci1OPIqoZI9SrgC8zIwnoOLTDwk07 | D5: 53 | E5: 43 | F5: 18 | G5: =D5*E5*F5/1000000 -> 0.041022 | H5: 4 | J5: 60 | K5: =J5*G5 -> 2.46132 | L5: Producto almacenable | M5: FERRAFORME MS | N5: TEC-0455-PLA | O5: EMCU8340494=CI&PL contenedor 36
A6: SOPORTE PARA CELULAR LUZ LED AZUL | B6: ORG-0290-AZL | C6: =VLOOKUP(B6,Sheet2!$1:$1048576,2,FALSE) -> https://drive.google.com/uc?export=download&id=1-Q8TI3uCvF8JdHCxuNpwz4gQ_vdHLb-A | D6: 44 | E6: 29 | F6: 20 | G6: =D6*E6*F6/1000000 -> 0.02552 | H6: 3 | J6: 49 | K6: =J6*G6 -> 1.25048 | L6: Producto almacenable | M6: FERRAFORME MS | N6: ORG-0290-AZL | O6: EMCU8340494=CI&PL contenedor 36
A7: BOLSA TRANSPARENTES CON MOÑO MULTICOLOR CH | B7: ORG-0291-PLA-CH | C7: =VLOOKUP(B7,Sheet2!$1:$1048576,2,FALSE) -> https://drive.google.com/uc?export=download&id=1dGZGfWfz_lfpyy-lumZ7Ag68GmY9gghi | D7: 55 | E7: 40 | F7: 31 | G7: =D7*E7*F7/1000000 -> 0.0682 | H7: 5 | J7: 10 | K7: =J7*G7 -> 0.682 | L7: Producto almacenable | M7: FERRAFORME MS | N7: ORG-0291-PLA-CH | O7: EMCU8340494=CI&PL contenedor 36
A8: BOLSA TRANSPARENTES CON MOÑO MULTICOLOR M | B8: ORG-0291-PLA-M | C8: =VLOOKUP(B8,Sheet2!$1:$1048576,2,FALSE) -> https://drive.google.com/uc?export=download&id=1dGZGfWfz_lfpyy-lumZ7Ag68GmY9gghi | D8: 55 | E8: 40 | F8: 31 | G8: =D8*E8*F8/1000000 -> 0.0682 | H8: 5 | J8: 8 | K8: =J8*G8 -> 0.5456 | L8: Producto almacenable | M8: FERRAFORME MS | N8: ORG-0291-PLA-M | O8: EMCU8340494=CI&PL contenedor 36
A9: BOLSA METALICA CHICA MULTI | B9: ORG-0293-MUL-M | C9: =VLOOKUP(B9,Sheet2!$1:$1048576,2,FALSE) -> https://drive.google.com/uc?export=download&id=1pAbe_qoKW1_vThNPocNrh7PDfv0kO1uG | D9: 51 | E9: 42 | F9: 42 | G9: =D9*E9*F9/1000000 -> 0.089964 | H9: 4 | J9: 75 | K9: =J9*G9 -> 6.7473 | L9: Producto almacenable | M9: FERRAFORME MS | N9: ORG-0293-MUL-M | O9: EMCU8340494=CI&PL contenedor 36
A10: LICUADORA PORTATIL AZUL | B10: TEC-0489-AZL | C10: =VLOOKUP(B10,Sheet2!$1:$1048576,2,FALSE) -> https://drive.google.com/uc?export=download&id=1K63z165bKvmzGqsHl03LN6cAwofkKpA8 | D10: 59 | E10: 49 | F10: 43 | G10: =D10*E10*F10/1000000 -> 0.124313 | H10: 2.3 | J10: 32 | K10: =J10*G10 -> 3.978016 | L10: Producto almacenable | M10: FERRAFORME MS | N10: TEC-0489-AZL | O10: EMCU8340494=CI&PL contenedor 36
A11: RASURADORA DORADA | B11: TEC-0496-PLA | C11: =VLOOKUP(B11,Sheet2!$1:$1048576,2,FALSE) -> https://drive.google.com/uc?export=download&id=1L555T6KbkROnZWPLSknTtUVqREDTHk8N | D11: 59 | E11: 46 | F11: 26 | G11: =D11*E11*F11/1000000 -> 0.070564 | H11: 2.1 | J11: 49 | K11: =J11*G11 -> 3.457636 | L11: Producto almacenable | M11: FERRAFORME MS | N11: TEC-0496-PLA | O11: EMCU8340494=CI&PL contenedor 36
A12: REGADERA PEQUEÑA BLANCO | B12: TEC-0444-MET | C12: =VLOOKUP(B12,Sheet2!$1:$1048576,2,FALSE) -> https://drive.google.com/uc?export=download&id=1lZylciM6Rx2q3-3H7RiLlZG3rqzRMm4H | D12: 55 | E12: 56 | F12: 33 | G12: =D12*E12*F12/1000000 -> 0.10164 | H12: 1.8 | J12: 20 | K12: =J12*G12 -> 2.0328 | L12: Producto almacenable | M12: FERRAFORME MS | N12: TEC-0444-MET | O12: EMCU8340494=CI&PL contenedor 36
A13: POSTURA NARIZ 3D NEGRO | B13: ACC-0028-BLN | C13: =VLOOKUP(B13,Sheet2!$1:$1048576,2,FALSE) -> https://drive.google.com/uc?export=download&id=1DYrUZ7isBMj4avxtwadfghM-LPWm-4xp | D13: 1 | E13: 1 | F13: 1 | G13: =D13*E13*F13/1000000 -> 1e-06 | H13: 0.4 | J13: 60 | K13: =J13*G13 -> 6e-05 | L13: Producto almacenable | M13: FERRAFORME MS | N13: ACC-0028-BLN | O13: EMCU8340494=CI&PL contenedor 36
A14: CUCHARA MEDIDORA NEGRO | B14: TEC-0445-NEG | C14: =VLOOKUP(B14,Sheet2!$1:$1048576,2,FALSE) -> https://drive.google.com/uc?export=download&id=1nf0w6-PT6McFTSLJKpmVFzrtiBy_JiO- | D14: 1 | E14: 1 | F14: 1 | G14: =D14*E14*F14/1000000 -> 1e-06 | H14: 1.6 | J14: 20 | K14: =J14*G14 -> 2e-05 | L14: Producto almacenable | M14: FERRAFORME MS | N14: TEC-0445-NEG | O14: EMCU8340494=CI&PL contenedor 36
A15: PLANCHA PARA CABELLO NEGRA | B15: TEC-0443-NEG-CUA | C15: =VLOOKUP(B15,Sheet2!$1:$1048576,2,FALSE) -> https://drive.google.com/uc?export=download&id=1Dx46MWH64QCq9ixDn1oFELyJHhzDmKf6 | D15: 59 | E15: 41 | F15: 36 | G15: =D15*E15*F15/1000000 -> 0.087084 | H15: 2.2 | J15: 50 | K15: =J15*G15 -> 4.3542 | L15: Producto almacenable | M15: FERRAFORME MS | N15: TEC-0443-NEG-CUA | O15: EMCU8340494=CI&PL contenedor 36
A16: RASURADORA 4 EN 1 AY-310 NEGRO | B16: TEC-0447-NEG | C16: =VLOOKUP(B16,Sheet2!$1:$1048576,2,FALSE) -> https://drive.google.com/uc?export=download&id=1c4eWiUfslJZcvOCExML_VFHkj4UATW7_ | D16: 44 | E16: 44 | F16: 38 | G16: =D16*E16*F16/1000000 -> 0.073568 | H16: 3.2 | J16: 60 | K16: =J16*G16 -> 4.41408 | L16: Producto almacenable | M16: FERRAFORME MS | N16: TEC-0447-NEG | O16: EMCU8340494=CI&PL contenedor 36
... A26: MICRO USB NEGRO | B26: TEC-0449-NEG | C26: =VLOOKUP(B26,Sheet2!$1:$1048576,2,FALSE) -> https://drive.google.com/uc?export=download&id=1ds2yqckkL2LBtFMtpnOv0qge-0fIl7eh | D26: 1 | E26: 1 | F26: 1 | G26: =D26*E26*F26/1000000 -> 1e-06 | H26: 2 | J26: 20 | K26: =J26*G26 -> 2e-05 | L26: Producto almacenable | M26: FERRAFORME MS | N26: TEC-0449-NEG | O26: EMCU8340494=CI&PL contenedor 36
A27: SOPORTE PARA CELULAR NARANJA | B27: TEC-0450-NAR | C27: =VLOOKUP(B27,Sheet2!$1:$1048576,2,FALSE) -> https://drive.google.com/uc?export=download&id=1HEwhSfhn1zHNT2DM9al8CVQjEL9ZaTYw | D27: 1 | E27: 1 | F27: 1 | G27: =D27*E27*F27/1000000 -> 1e-06 | J27: 50 | K27: =J27*G27 -> 5e-05 | L27: Producto almacenable | M27: FERRAFORME MS | N27: TEC-0450-NAR | O27: EMCU8340494=CI&PL contenedor 36
A28: SOPORTE PARA CELULAR AMARILLO | B28: TEC-0450-AMA | C28: =VLOOKUP(B28,Sheet2!$1:$1048576,2,FALSE) -> https://drive.google.com/uc?export=download&id=1HEwhSfhn1zHNT2DM9al8CVQjEL9ZaTYw | D28: 1 | E28: 1 | F28: 1 | G28: =D28*E28*F28/1000000 -> 1e-06 | J28: 49 | K28: =J28*G28 -> 4.9e-05 | L28: Producto almacenable | M28: FERRAFORME MS | N28: TEC-0450-AMA | O28: EMCU8340494=CI&PL contenedor 36
A29: SOPORTE PARA CELULAR MORADO | B29: TEC-0450-MOR | C29: =VLOOKUP(B29,Sheet2!$1:$1048576,2,FALSE) -> https://drive.google.com/uc?export=download&id=1HEwhSfhn1zHNT2DM9al8CVQjEL9ZaTYw | D29: 1 | E29: 1 | F29: 1 | G29: =D29*E29*F29/1000000 -> 1e-06 | J29: 49 | K29: =J29*G29 -> 4.9e-05 | L29: Producto almacenable | M29: FERRAFORME MS | N29: TEC-0450-MOR | O29: EMCU8340494=CI&PL contenedor 36
A30: SOPORTE PARA TELEFONO NEGRO | B30: TEC-0450-NEG | C30: =VLOOKUP(B30,Sheet2!$1:$1048576,2,FALSE) -> https://drive.google.com/uc?export=download&id=1HEwhSfhn1zHNT2DM9al8CVQjEL9ZaTYw | D30: 1 | E30: 1 | F30: 1 | G30: =D30*E30*F30/1000000 -> 1e-06 | H30: 2 | J30: 16 | K30: =J30*G30 -> 1.6e-05 | L30: Producto almacenable | M30: FERRAFORME MS | N30: TEC-0450-NEG | O30: EMCU8340494=CI&PL contenedor 36
A31: CARGADOR POWER AMARILLO | B31: TEC-0488-AMA | C31: =VLOOKUP(B31,Sheet2!$1:$1048576,2,FALSE) -> https://drive.google.com/uc?export=download&id=1OvuJfyO0T3pa5uVxSX341A91Jxj4ksKx | D31: 50 | E31: 45 | F31: 33 | G31: =D31*E31*F31/1000000 -> 0.07425 | H31: 0.6 | J31: 130 | K31: =J31*G31 -> 9.6525 | L31: Producto almacenable | M31: FERRAFORME MS | N31: TEC-0488-AMA | O31: EMCU8340494=CI&PL contenedor 36
A32: EQUIPO DE OSMOSIS | B32: TEC-0451-MET | C32: =VLOOKUP(B32,Sheet2!$1:$1048576,2,FALSE) -> https://drive.google.com/uc?export=download&id=1FqB_3LwvD4nn3zJQ8Y9bbK66XjzCHSg6 | D32: 98 | E32: 52 | F32: 47 | G32: =D32*E32*F32/1000000 -> 0.239512 | H32: 250 | J32: 1 | K32: =J32*G32 -> 0.239512 | L32: Producto almacenable | M32: FERRAFORME MS | N32: TEC-0451-MET | O32: EMCU8340494=CI&PL contenedor 36
A33: EVEPER 40A 12-24V MPPT CONTROLADOR DE CARGA SOLAR 100VOC NEGRO | B33: TEC-0453-NEG | C33: =VLOOKUP(B33,Sheet2!$1:$1048576,2,FALSE) -> https://drive.google.com/uc?export=download&id=11_q1F4MCNxWlyiFJkTDlbSPyxN3F015D | D33: 57 | E33: 43 | F33: 23 | G33: =D33*E33*F33/1000000 -> 0.056373 | H33: 1.7 | K33: =J33*G33 -> 0 | L33: Producto almacenable | M33: FERRAFORME MS | N33: TEC-0453-NEG | O33: EMCU8340494=CI&PL contenedor 36
A34: CONTROLADORA DE CARGA SOLAR 12/48VDC NEGRO | B34: TEC-0493-NEG | C34: =VLOOKUP(B34,Sheet2!$1:$1048576,2,FALSE) -> https://drive.google.com/uc?export=download&id=1_Zs4tt4mlCTN2kcNVd1KAqocartKJlok | D34: 44 | E34: 43 | F34: 40 | G34: =D34*E34*F34/1000000 -> 0.07568 | H34: 11.3 | J34: 20 | K34: =J34*G34 -> 1.5136 | L34: Producto almacenable | M34: FERRAFORME MS | N34: TEC-0493-NEG | O34: EMCU8340494=CI&PL contenedor 36
A35: CONTROLADOR DE CARGA SOLAR 100V GRIS | B35: TEC-0491-PLA | C35: =VLOOKUP(B35,Sheet2!$1:$1048576,2,FALSE) -> https://drive.google.com/uc?export=download&id=1Nm7la3X5HBAYsI94x-7sFeHpeN5tHrgT | D35: 42 | E35: 31 | F35: 18 | G35: =D35*E35*F35/1000000 -> 0.023436 | H35: 65 | J35: 10 | K35: =J35*G35 -> 0.23436 | L35: Producto almacenable | M35: FERRAFORME MS | N35: TEC-0491-PLA | O35: EMCU8340494=CI&PL contenedor 36
A36: COVERTIDOR SOLAR 1600W GRIS C NARANJA | B36: TEC-0454-GRI | C36: =VLOOKUP(B36,Sheet2!$1:$1048576,2,FALSE) -> https://drive.google.com/uc?export=download&id=1t2ame1o8s8Xis5e90P1eqSBwvd1zbgpa | D36: 53 | E36: 40 | F36: 21 | G36: =D36*E36*F36/1000000 -> 0.04452 | H36: 192 | J36: 1 | K36: =J36*G36 -> 0.04452 | L36: Producto almacenable | M36: FERRAFORME MS | N36: TEC-0454-GRI | O36: EMCU8340494=CI&PL contenedor 36
A37: PANEL SOLAR | B37: EST-0061-NEG | C37: =VLOOKUP(B37,Sheet2!$1:$1048576,2,FALSE) -> https://drive.google.com/uc?export=download&id=1D62UAiBsatvmjB9-Bf898Xz6LBldS03r | D37: 50 | E37: 36 | F37: 36 | G37: =D37*E37*F37/1000000 -> 0.0648 | H37: 6.18 | J37: 10 | K37: =J37*G37 -> 0.648 | L37: Producto almacenable | M37: FERRAFORME MS | N37: EST-0061-NEG | O37: EMCU8340494=CI&PL contenedor 36
A38: TARJETA MADRE INVERSOR SOLAR | B38: TEC-0456-PLA | C38: =VLOOKUP(B38,Sheet2!$1:$1048576,2,FALSE) -> https://drive.google.com/uc?export=download&id=10amukYXc-8I5P60IWEH3Ul6_s7G0_C5q | D38: 48 | E38: 37 | F38: 17 | G38: =D38*E38*F38/1000000 -> 0.030192 | H38: 71 | J38: 1 | K38: =J38*G38 -> 0.030192 | L38: Producto almacenable | M38: FERRAFORME MS | N38: TEC-0456-PLA | O38: EMCU8340494=CI&PL contenedor 36
A39: MONITOR PORTATIL XBOX TELEFONO NEGRO | B39: TEC-0492-MUL | C39: =VLOOKUP(B39,Sheet2!$1:$1048576,2,FALSE) -> https://drive.google.com/uc?export=download&id=1JmJtcla17vu3vVJWuHcislVKF5IAcB-S | D39: 44 | E39: 41 | F39: 29 | G39: =D39*E39*F39/1000000 -> 0.052316 | H39: 45 | J39: 10 | K39: =J39*G39 -> 0.52316 | L39: Producto almacenable | M39: FERRAFORME MS | N39: TEC-0492-MUL | O39: EMCU8340494=CI&PL contenedor 36
A40: LUCES DE ESCENARIO DE ESFERA 110X100X15MM NEGRO | B40: TEC-0458-NEG | C40: =VLOOKUP(B40,Sheet2!$1:$1048576,2,FALSE) -> https://drive.google.com/uc?export=download&id=1NRXqWIjJjJq5XYebp-sS5SEdIXLXEJIV | D40: 62 | E40: 53 | F40: 25 | G40: =D40*E40*F40/1000000 -> 0.08215 | H40: 18.87 | J40: 50 | K40: =J40*G40 -> 4.1075 | L40: Producto almacenable | M40: FERRAFORME MS | N40: TEC-0458-NEG | O40: EMCU8340494=CI&PL contenedor 36
A41: MAQUINA DE HUMO NEGRO | B41: TEC-0757-NEG | C41: =VLOOKUP(B41,Sheet2!$1:$1048576,2,FALSE) -> https://drive.google.com/uc?export=download&id=1z8ICtB8FcvDDfeREQN6nv_uA1g-fhjgq | D41: 42 | E41: 35 | F41: 30 | G41: =D41*E41*F41/1000000 -> 0.0441 | H41: 61.05 | J41: 36 | K41: =J41*G41 -> 1.5876 | L41: Producto almacenable | M41: FERRAFORME MS | N41: TEC-0757-NEG | O41: EMCU8340494=CI&PL contenedor 36
A42: MAQUINA DE HUMO 9 LUCES PLATA | B42: TEC-0759-PLA | C42: =VLOOKUP(B42,Sheet2!$1:$1048576,2,FALSE) -> https://drive.google.com/uc?export=download&id=1Wh7rCji2Xde_BbJDnF8gtyLxeUeeO-Y0 | D42: 52 | E42: 47 | F42: 39 | G42: =D42*E42*F42/1000000 -> 0.095316 | H42: 146.3 | J42: 4 | K42: =J42*G42 -> 0.381264 | L42: Producto almacenable | M42: FERRAFORME MS | N42: TEC-0759-PLA | O42: EMCU8340494=CI&PL contenedor 36
A43: CABEZAS MOVILES LED 200MRAYO DJ NEGRO | B43: TEC-0461-NEG | C43: =VLOOKUP(B43,Sheet2!$1:$1048576,2,FALSE) -> https://drive.google.com/uc?export=download&id=1CuhdK5GRhTzUYmjLn6_3sPi0YYRT8mJU | D43: 57 | E43: 48 | F43: 36 | G43: =D43*E43*F43/1000000 -> 0.098496 | H43: 330 | J43: 4 | K43: =J43*G43 -> 0.393984 | L43: Producto almacenable | M43: FERRAFORME MS | N43: TEC-0461-NEG | O43: EMCU8340494=CI&PL contenedor 36
A44: LUZ LASER 5 EN 1 AUDIORITMICAS NEGRO | B44: TEC-0460-MUL | C44: =VLOOKUP(B44,Sheet2!$1:$1048576,2,FALSE) -> https://drive.google.com/uc?export=download&id=1S_Ng5A6mi51ZkZ1UQqhAkgNHgFOKYxlS | D44: 52 | E44: 47 | F44: 42 | G44: =D44*E44*F44/1000000 -> 0.102648 | H44: 127.65 | J44: 12 | K44: =J44*G44 -> 1.231776 | L44: Producto almacenable | M44: FERRAFORME MS | N44: TEC-0460-MUL | O44: EMCU8340494=CI&PL contenedor 36
A45: 2PC CAÑON DE LEDS AUDIORITMICO MULTICOLOR | B45: TEC-0758-MUL | C45: =VLOOKUP(B45,Sheet2!$1:$1048576,2,FALSE) -> https://drive.google.com/uc?export=download&id=1_gpHxO4GCX2bjReYvL8tRM7kMjvXohGb | D45: 48 | E45: 46 | F45: 45 | G45: =D45*E45*F45/1000000 -> 0.09936 | H45: 66 | J45: 6 | K45: =J45*G45 -> 0.59616 | L45: Producto almacenable | M45: FERRAFORME MS | N45: TEC-0758-MUL | O45: EMCU8340494=CI&PL contenedor 36
... A54: CEPILLO RIZADOR TERMICO NARANJA | B54: ACC-0231-NAR | C54: =VLOOKUP(B54,Sheet2!$1:$1048576,2,FALSE) -> https://drive.google.com/uc?export=download&id=1oyyNlrneK9k986CJO58i1zPE9yAqRKuu | D54: 57 | E54: 36 | F54: 35 | G54: =D54*E54*F54/1000000 -> 0.07182 | H54: 11 | J54: 20 | K54: =J54*G54 -> 1.4364 | L54: Producto almacenable | M54: FERRAFORME MS | N54: ACC-0231-NAR | O54: EMCU8340494=CI&PL contenedor 36
A55: CORTINAS VERDES | B55: MUE-0147-VER | D55: 55 | E55: 41 | F55: 30 | G55: =D55*E55*F55/1000000 -> 0.06765 | H55: 10 | J55: 16 | K55: =J55*G55 -> 1.0824 | L55: Producto almacenable | M55: FERRAFORME MS | N55: MUE-0147-VER | O55: EMCU8340494=CI&PL contenedor 36
A56: CORTINAS BLANCAS | B56: MUE-0147-BLN | D56: 55 | E56: 41 | F56: 30 | G56: =D56*E56*F56/1000000 -> 0.06765 | H56: 10 | J56: 16 | K56: =J56*G56 -> 1.0824 | L56: Producto almacenable | M56: FERRAFORME MS | N56: MUE-0147-BLN | O56: EMCU8340494=CI&PL contenedor 36
A57: CORTINAS AMARILLAS | B57: MUE-0147-AMA | D57: 55 | E57: 41 | F57: 30 | G57: =D57*E57*F57/1000000 -> 0.06765 | H57: 10 | J57: 16 | K57: =J57*G57 -> 1.0824 | L57: Producto almacenable | M57: FERRAFORME MS | N57: MUE-0147-AMA | O57: EMCU8340494=CI&PL contenedor 36
...

Sheet Sheet2
A1: SKU | B1: url_imagen
A2: ORG-0304-PLA-70X30 | B2: https://drive.google.com/uc?export=download&id=18nK3vxiLPAzynUtePD5kAaKlGypYFmVg
A3: ORG-0304-PLA-100X150 | B3: https://drive.google.com/uc?export=download&id=18nK3vxiLPAzynUtePD5kAaKlGypYFmVg
A4: TEC-0056-PLA | B4: https://drive.google.com/uc?export=download&id=1ydANkLmJqrIfr-ucx2PAO2rir7Qo_7k2
A5: MUE-0082-NEG | B5: https://drive.google.com/uc?export=download&id=1A5Dh9rFBjpsAb-YwuLIS44DUmr5OOhcD
A6: MUE-0079-NEG | B6: https://drive.google.com/uc?export=download&id=1i-80pFiTRxxSFMeFocrK2NFjxLjcpFvH
A7: TEC-0762-EST | B7: https://drive.google.com/uc?export=download&id=1d2sQ2jJ_VTr2n2tEOPA7Jfdj3tlQD-Te
A8: TEC-0571-MET | B8: https://drive.google.com/uc?export=download&id=1IogcfAcdipnc8I7DsP_iw0HPCbmMwt06
A9: TEC-0593-NEG | B9: https://drive.google.com/uc?export=download&id=1SDbfwk4BcVuOgsqHjcyoq5ZbovYrjqLq
A10: TEC-0594-NEG | B10: https://drive.google.com/uc?export=download&id=1EfgskujiA0cVpdSqjmZ4LCGSP61o93mY
A11: TEC-0595-PLA | B11: https://drive.google.com/uc?export=download&id=1WIE5XP46AAwtQZb69pIxxCIRYrFRzpBn
A12: TEC-0596-MET | B12: https://drive.google.com/uc?export=download&id=1eRynMlkgDz0Cz_hOVEvwYVIxyDNVLizK
... A157: CALZ-0119-NEG-37 | B157: https://drive.google.com/uc?export=download&id=1lAggtp_8tO31MHoeh7nkYThzGA371oRc
B158: https://drive.google.com/uc?export=download&id=1lAggtp_8tO31MHoeh7nkYThzGA371oRc
A159: CALZ-0119-NEG-39 | B159: https://drive.google.com/uc?export=download&id=1lAggtp_8tO31MHoeh7nkYThzGA371oRc
A160: CALZ-0119-NEG-40 | B160: https://drive.google.com/uc?export=download&id=1lAggtp_8tO31MHoeh7nkYThzGA371oRc
A161: CALZ-0119-ROS-36 | B161: https://drive.google.com/uc?export=download&id=1lAggtp_8tO31MHoeh7nkYThzGA371oRc
A162: CALZ-0119-ROS-37 | B162: https://drive.google.com/uc?export=download&id=1lAggtp_8tO31MHoeh7nkYThzGA371oRc
A163: CALZ-0119-ROS-39 | B163: https://drive.google.com/uc?export=download&id=1lAggtp_8tO31MHoeh7nkYThzGA371oRc
A164: TEC-0061-AMA | B164: https://drive.google.com/uc?export=download&id=1LULXYCh0JWBhuR7QDuBUPGYzeWufp8Ln
A165: TEC-0061-AZL | B165: https://drive.google.com/uc?export=download&id=1LULXYCh0JWBhuR7QDuBUPGYzeWufp8Ln
A166: CALZ-0016-ROS-23 | B166: https://drive.google.com/uc?export=download&id=1tGo2IKIdxm_e9VSFICm3T4etO5AkjQ0I
A167: CALZ-0016-ROS-25 | B167: https://drive.google.com/uc?export=download&id=1tGo2IKIdxm_e9VSFICm3T4etO5AkjQ0I
A168: CALZ-0016-ROS-26 | B168: https://drive.google.com/uc?export=download&id=1tGo2IKIdxm_e9VSFICm3T4etO5AkjQ0I
A169: CALZ-0016-ROS-27 | B169: https://drive.google.com/uc?export=download&id=1tGo2IKIdxm_e9VSFICm3T4etO5AkjQ0I
A170: CALZ-0016-ROS-24 | B170: https://drive.google.com/uc?export=download&id=1tGo2IKIdxm_e9VSFICm3T4etO5AkjQ0I
... A652: CALZ-0123-BLN-GRI-39 | B652: https://drive.google.com/uc?export=download&id=1DnvHqs8itDAxli4_-TVYlOENqZfUQXCa
B653: https://drive.google.com/uc?export=download&id=10xL0m2tPSbT-guuH37Y2IKwhlSDJsRgY
A654: CALZ-0123-BLN-GRI-40 | B654: https://drive.google.com/uc?export=download&id=1DnvHqs8itDAxli4_-TVYlOENqZfUQXCa
A655: TEC-0568-GRI | B655: https://drive.google.com/uc?export=download&id=1Dsp09L7qX1NSLbGHQ8uiYJwa1hggeDYv
A656: CALZ-0142-BLN-AZL-36 | B656: https://drive.google.com/uc?export=download&id=1UpDVPzRZT4hruq0yas16tmxLasoqxF6o
A657: CALZ-0142-BLN-AZL-37 | B657: https://drive.google.com/uc?export=download&id=1UpDVPzRZT4hruq0yas16tmxLasoqxF6o
A658: CALZ-0142-BLN-AZL-39 | B658: https://drive.google.com/uc?export=download&id=1UpDVPzRZT4hruq0yas16tmxLasoqxF6o
A659: CALZ-0142-BLN-AMA-37 | B659: https://drive.google.com/uc?export=download&id=1UpDVPzRZT4hruq0yas16tmxLasoqxF6o
A660: CALZ-0142-BLN-AMA-39 | B660: https://drive.google.com/uc?export=download&id=1UpDVPzRZT4hruq0yas16tmxLasoqxF6o
A661: CALZ-0142-BLN-AMA-40 | B661: https://drive.google.com/uc?export=download&id=1UpDVPzRZT4hruq0yas16tmxLasoqxF6o
A662: CALZ-0142-BLN-AZL-36 | B662: https://drive.google.com/uc?export=download&id=1UpDVPzRZT4hruq0yas16tmxLasoqxF6o
A663: CALZ-0142-BLN-AZL-37 | B663: https://drive.google.com/uc?export=download&id=1UpDVPzRZT4hruq0yas16tmxLasoqxF6o
A664: CALZ-0142-BLN-AZL-38 | B664: https://drive.google.com/uc?export=download&id=1UpDVPzRZT4hruq0yas16tmxLasoqxF6o
A665: CALZ-0142-BLN-AZL-39 | B665: https://drive.google.com/uc?export=download&id=1UpDVPzRZT4hruq0yas16tmxLasoqxF6o
...
